[2025-10-03T14:29:47.977+0000] {taskinstance.py:1159} INFO - Dependencies all met for dep_context=non-requeueable deps ti=<TaskInstance: initial_data_pipeline.generate_initial_data manual__2025-10-03T14:29:46.134830+00:00 [queued]>
[2025-10-03T14:29:47.983+0000] {taskinstance.py:1159} INFO - Dependencies all met for dep_context=requeueable deps ti=<TaskInstance: initial_data_pipeline.generate_initial_data manual__2025-10-03T14:29:46.134830+00:00 [queued]>
[2025-10-03T14:29:47.983+0000] {taskinstance.py:1361} INFO - Starting attempt 1 of 1
[2025-10-03T14:29:47.993+0000] {taskinstance.py:1382} INFO - Executing <Task(PythonOperator): generate_initial_data> on 2025-10-03 14:29:46.134830+00:00
[2025-10-03T14:29:47.999+0000] {standard_task_runner.py:57} INFO - Started process 256 to run task
[2025-10-03T14:29:48.003+0000] {standard_task_runner.py:84} INFO - Running: ['***', 'tasks', 'run', 'initial_data_pipeline', 'generate_initial_data', 'manual__2025-10-03T14:29:46.134830+00:00', '--job-id', '10', '--raw', '--subdir', 'DAGS_FOLDER/initial_data_pipeline.py', '--cfg-path', '/tmp/tmp5epbywpf']
[2025-10-03T14:29:48.006+0000] {standard_task_runner.py:85} INFO - Job 10: Subtask generate_initial_data
[2025-10-03T14:29:48.048+0000] {task_command.py:415} INFO - Running <TaskInstance: initial_data_pipeline.generate_initial_data manual__2025-10-03T14:29:46.134830+00:00 [running]> on host 38cb3f89ee79
[2025-10-03T14:29:48.121+0000] {taskinstance.py:1660} INFO - Exporting env vars: AIRFLOW_CTX_DAG_OWNER='***' AIRFLOW_CTX_DAG_ID='initial_data_pipeline' AIRFLOW_CTX_TASK_ID='generate_initial_data' AIRFLOW_CTX_EXECUTION_DATE='2025-10-03T14:29:46.134830+00:00' AIRFLOW_CTX_TRY_NUMBER='1' AIRFLOW_CTX_DAG_RUN_ID='manual__2025-10-03T14:29:46.134830+00:00'
[2025-10-03T14:29:48.155+0000] {taskinstance.py:1943} ERROR - Task failed with exception
Traceback (most recent call last):
  File "/home/airflow/.local/lib/python3.8/site-packages/airflow/operators/python.py", line 192, in execute
    return_value = self.execute_callable()
  File "/home/airflow/.local/lib/python3.8/site-packages/airflow/operators/python.py", line 209, in execute_callable
    return self.python_callable(*self.op_args, **self.op_kwargs)
  File "/opt/airflow/dags/initial_data_pipeline.py", line 17, in generate_initial_data
    raise Exception(f"Script failed: {result.stderr}")
Exception: Script failed: Traceback (most recent call last):
  File "/opt/***/scripts/generate_data.py", line 4, in <module>
    from faker import Faker
ModuleNotFoundError: No module named 'faker'

[2025-10-03T14:29:48.165+0000] {taskinstance.py:1400} INFO - Marking task as FAILED. dag_id=initial_data_pipeline, task_id=generate_initial_data, execution_date=20251003T142946, start_date=20251003T142947, end_date=20251003T142948
[2025-10-03T14:29:48.180+0000] {standard_task_runner.py:104} ERROR - Failed to execute job 10 for task generate_initial_data (Script failed: Traceback (most recent call last):
  File "/opt/***/scripts/generate_data.py", line 4, in <module>
    from faker import Faker
ModuleNotFoundError: No module named 'faker'
; 256)
[2025-10-03T14:29:48.214+0000] {local_task_job_runner.py:228} INFO - Task exited with return code 1
[2025-10-03T14:29:48.242+0000] {taskinstance.py:2784} INFO - 0 downstream tasks scheduled from follow-on schedule check
